<?xml version="1.0"?>
<robot name="myfirst">
  <material name="blue">
    <color rgba="0 0 0.8 1"/>
  </material>
  <link name="base_link">
    <visual>
      <origin
        xyz="0 0 0"
        rpy="0 0 0" />
      <geometry>
        <box size="0.6 0.1 0.02"/>
      </geometry>
    </visual>
  </link>

  <link name="link_0">
    <visual>
      <geometry>
        <cylinder length="0.1" radius="0.05"/>
      </geometry>
      <origin rpy="0 0 0.02" xyz="0 0 0.05"/>
    </visual>
  </link>


  <joint name="joint_1" type="revolute">
    <axis xyz="0 0 1"/>
    <limit effort="1000.0" lower="-1.0" upper="1.0" velocity="0.5"/>
    <parent link="base_link"/>
    <child link="link_0"/>
    <origin rpy="0 0 0" xyz="0 0 0.01"/>
  </joint>

  <link name="link_1">
    <visual>
      <geometry>
        <box size="0.2 0.1 0.02"/>
      </geometry>
      <origin rpy="0 1.57075 0" xyz="0 0 0.1"/>
    </visual>
  </link>

  <joint name="joint_2" type="revolute">
    <axis xyz="0 1 0"/>
    <limit effort="1000.0" lower="0.0" upper="1.0" velocity="0.5"/>
    <parent link="link_0"/>
    <child link="link_1"/>
    <origin rpy="0 0 0" xyz="0 0 0.1"/>
  </joint>

  <link name="link_2">
    <visual>
      <geometry>
        <box size="0.2 0.1 0.02"/>
      </geometry>
      <origin rpy="0 2.1075 0" xyz="0.05 0 0.08"/>
    </visual>
  </link>

  <joint name="joint_3" type="revolute">
    <axis xyz="0 1 0"/>
    <limit effort="1000.0" lower="0.0" upper="1.0" velocity="0.5"/>
    <parent link="link_1"/>
    <child link="link_2"/>
    <origin rpy="0 0 0" xyz="0 0 0.2"/>
  </joint>

  <link name="link_3">
    <visual>
      <geometry>
        <box size="0.1 0.1 0.02"/>
      </geometry>
      <origin rpy="0 3.1075 0" xyz="0.05 0 0"/>
    </visual>
  </link>

  <joint name="joint_4" type="revolute">
    <axis xyz="0 1 0"/>
    <limit effort="1000.0" lower="0.0" upper="1.0" velocity="0.5"/>
    <parent link="link_2"/>
    <child link="link_3"/>
    <origin rpy="0 0 0" xyz="0.11 0 0.16"/>
  </joint>

  <link name="wheel_gripper">
    <visual>
      <geometry>
        <cylinder length="0.02" radius="0.02"/>
      </geometry>
      <origin rpy="0 1.57075 0" xyz="0.01 0 0"/>
    </visual>
  </link>

  <joint name="joint_5" type="revolute">
    <axis xyz="1 0 0"/>
    <limit effort="1000.0" lower="0.0" upper="1.0" velocity="0.5"/>
    <parent link="link_3"/>
    <child link="wheel_gripper"/>
    <origin rpy="0 0 0" xyz="0.1 0 0"/>
  </joint>

  <link name="gripper">
    <visual>
      <geometry>
        <cylinder length="0.05" radius="0.01"/>
      </geometry>
      <origin rpy="0 1.57075 0" xyz="0.025 0 0"/>
      <material name="blue"/>
    </visual>
  </link>

  <joint name="wheel_gripper_to_gripper" type="fixed">
    <parent link="wheel_gripper"/>
    <child link="gripper"/>
    <origin rpy="0 0 0" xyz="0.02 0 0"/>
  </joint>


</robot>
